Workbook

Sheet HISP
A2: Household Characteristics | B2: Treatment group(n=2964) | C2: Comparison group(n=2664) | D2: Difference | E2: t-test
A3: Health expenditures(US$ yearly per capita) | B3: 14.49 | C3: 14.57 | D3: -0.08 | E3: -0.73
A4: Head of Household's age(years) | B4: 41.66 | C4: 42.29 | D4: -0.64 | E4: -1.69
A5: Spouse's age(years) | B5: 36.84 | C5: 36.88 | D5: 0.04 | E5: 0.12
A6: Head of household's education (years) | B6: 2.97 | C6: 2.81 | D6: 0.16 | E6: 2.3
A7: Spouse's education(years) | B7: 2.7 | C7: 2.67 | D7: 0.03 | E7: 0.43
A8: Head of Household is female=1 | B8: 0.07 | C8: 0.08 | D8: -0.01 | E8: -0.58
A9: Indigenious=1 | B9: 0.43 | C9: 0.42 | D9: 0.01 | E9: 0.69
A10: Number of Household members | B10: 5.77 | C10: 5.71 | D10: 0.06 | E10: 1.12
A11: Has dirt floor=1 | B11: 0.72 | C11: 0.73 | D11: -0.01 | E11: -1.09
A12: Has bathroom=1 | B12: 0.57 | C12: 0.56 | D12: 0.01 | E12: 1.04
A13: Hectares of land | B13: 1.68 | C13: 1.72 | D13: -0.04 | E13: -0.57
A14: Distance to hospital(km) | B14: 109.2 | C14: 106.29 | D14: 2.91 | E14: 2.57

Sheet KRWSIP_Program_Baseline Data
A2: Baseline Data of Evaluation Sample
O3: Treatment Group | P3: Comparison Group | Q3: Difference
O4: Sample Mean | P4: Sample mean
A5: Household ID | B5: Village | C5: Household_Size | D5: Monthly_Household_Income | E5: Current Water Source | F5: Annual Health Expenditure | G5: Time to collect Water | H5: Distance to Health facility | I5: Random No. | J5: Treatment | L5: =C5 -> Household_Size | O5: =AVERAGE(C6:C205) -> 4.98 | P5: =AVERAGE(C206:C405) -> 5.215 | Q5: =P5-O5 -> 0.235 | S5: Treatment Income | T5: Control Income | U5: Treatment ANE | V5: Control-ANE | W5: TRG- Time | X5: GTG-Time | Y5: TRG- Distance | Z5: CTr-Distance
A6: ="HH"&TEXT(ROW()-5,"000") -> HH001 | B6: Oloitoktok A | C6: 2 | D6: 17533 | E6: Borehole | F6: 3387 | G6: 96 | H6: 14.1 | I6: 0.14715147 | J6: 1 | L6: =D5 -> Monthly_Household_Income | O6: =AVERAGE(D6:D205) -> 28408.135 | P6: =AVERAGE(D206:D405) -> 27962.045 | Q6: =P6-O6 -> -446.09 | S6: =IF($J6=1,D6,"") -> 17533 | T6: =IF($J206=0, D206,"") -> 23861 | U6: =IF($J6=1,F6,"") -> 3387 | V6: =IF($J206=0,F206,"") -> 5945 | W6: =IF($J6=1,G6,"") -> 96 | X6: =IF($J206=0,G206,"") -> 91 | Y6: =IF($J6=1,H6,"") -> 14.1 | Z6: =IF($J206=0,H206,"") -> 3.5
A7: ="HH"&TEXT(ROW()-5,"000") -> HH002 | B7: Oloitoktok A | C7: 3 | D7: 28095 | E7: Rainwater | F7: 3285 | G7: 66 | H7: 8.5 | I7: 0.21625297 | J7: 1 | L7: =F5 -> Annual Health Expenditure | O7: =AVERAGE(F6:F204) -> 4730.1608 | P7: =AVERAGE(F206:F405) -> 4827.065 | Q7: =P7-O7 -> 96.904196 | S7: =IF($J7=1,D7,"") -> 28095 | T7: =IF($J207=0, D207,"") -> 30323 | U7: =IF($J7=1,F7,"") -> 3285 | V7: =IF($J207=0,F207,"") -> 5395 | W7: =IF($J7=1,G7,"") -> 66 | X7: =IF($J207=0,G207,"") -> 29 | Y7: =IF($J7=1,H7,"") -> 8.5 | Z7: =IF($J207=0,H207,"") -> 6.7
A8: ="HH"&TEXT(ROW()-5,"000") -> HH003 | B8: Namanga | C8: 7 | D8: 35172 | E8: Rainwater | F8: 6752 | G8: 42 | H8: 1.9 | I8: 0.87272995 | J8: 1 | L8: =G5 -> Time to collect Water | O8: =AVERAGE(G6:G205) -> 68.45 | P8: =AVERAGE(G206:G405) -> 67.855 | Q8: =P8-O8 -> -0.595 | S8: =IF($J8=1,D8,"") -> 35172 | T8: =IF($J208=0, D208,"") -> 27664 | U8: =IF($J8=1,F8,"") -> 6752 | V8: =IF($J208=0,F208,"") -> 6942 | W8: =IF($J8=1,G8,"") -> 42 | X8: =IF($J208=0,G208,"") -> 60 | Y8: =IF($J8=1,H8,"") -> 1.9 | Z8: =IF($J208=0,H208,"") -> 11.2
A9: ="HH"&TEXT(ROW()-5,"000") -> HH004 | B9: Oloitoktok B | C9: 8 | D9: 24958 | E9: Rainwater | F9: 4888 | G9: 64 | H9: 12.3 | I9: 0.43294112 | J9: 1 | L9: =H5 -> Distance to Health facility | O9: =AVERAGE(H6:H205) -> 8.1255 | P9: =AVERAGE(H206:H405) -> 7.6565 | Q9: =P9-O9 -> -0.469 | S9: =IF($J9=1,D9,"") -> 24958 | T9: =IF($J209=0, D209,"") -> 22468 | U9: =IF($J9=1,F9,"") -> 4888 | V9: =IF($J209=0,F209,"") -> 2752 | W9: =IF($J9=1,G9,"") -> 64 | X9: =IF($J209=0,G209,"") -> 50 | Y9: =IF($J9=1,H9,"") -> 12.3 | Z9: =IF($J209=0,H209,"") -> 13.9
A10: ="HH"&TEXT(ROW()-5,"000") -> HH005 | B10: Oloitoktok B | C10: 4 | D10: 35107 | E10: Borehole | F10: 5527 | G10: 20 | H10: 14.7 | I10: 0.66002778 | J10: 1 | S10: =IF($J10=1,D10,"") -> 35107 | T10: =IF($J210=0, D210,"") -> 36674 | U10: =IF($J10=1,F10,"") -> 5527 | V10: =IF($J210=0,F210,"") -> 4730 | W10: =IF($J10=1,G10,"") -> 20 | X10: =IF($J210=0,G210,"") -> 113 | Y10: =IF($J10=1,H10,"") -> 14.7 | Z10: =IF($J210=0,H210,"") -> 7.2
A11: ="HH"&TEXT(ROW()-5,"000") -> HH006 | B11: Namanga | C11: 4 | D11: 33442 | E11: Vendor | F11: 4457 | G11: 92 | H11: 11.3 | I11: 0.79246542 | J11: 1 | S11: =IF($J11=1,D11,"") -> 33442 | T11: =IF($J211=0, D211,"") -> 21108 | U11: =IF($J11=1,F11,"") -> 4457 | V11: =IF($J211=0,F211,"") -> 3739 | W11: =IF($J11=1,G11,"") -> 92 | X11: =IF($J211=0,G211,"") -> 58 | Y11: =IF($J11=1,H11,"") -> 11.3 | Z11: =IF($J211=0,H211,"") -> 10.4
A12: ="HH"&TEXT(ROW()-5,"000") -> HH007 | B12: Oloitoktok B | C12: 2 | D12: 34829 | E12: Vendor | F12: 4225 | G12: 60 | H12: 10.5 | I12: 0.27764315 | J12: 1 | S12: =IF($J12=1,D12,"") -> 34829 | T12: =IF($J212=0, D212,"") -> 27803 | U12: =IF($J12=1,F12,"") -> 4225 | V12: =IF($J212=0,F212,"") -> 5478 | W12: =IF($J12=1,G12,"") -> 60 | X12: =IF($J212=0,G212,"") -> 120 | Y12: =IF($J12=1,H12,"") -> 10.5 | Z12: =IF($J212=0,H212,"") -> 14.2
A13: ="HH"&TEXT(ROW()-5,"000") -> HH008 | B13: Kiserian | C13: 3 | D13: 33149 | E13: Vendor | F13: 2764 | G13: 70 | H13: 11.7 | I13: 0.74421109 | J13: 1 | S13: =IF($J13=1,D13,"") -> 33149 | T13: =IF($J213=0, D213,"") -> 37239 | U13: =IF($J13=1,F13,"") -> 2764 | V13: =IF($J213=0,F213,"") -> 7041 | W13: =IF($J13=1,G13,"") -> 70 | X13: =IF($J213=0,G213,"") -> 114 | Y13: =IF($J13=1,H13,"") -> 11.7 | Z13: =IF($J213=0,H213,"") -> 4.8
A14: ="HH"&TEXT(ROW()-5,"000") -> HH009 | B14: Kiserian | C14: 6 | D14: 24162 | E14: Rainwater | F14: 5668 | G14: 37 | H14: 13.7 | I14: 0.41983377 | J14: 1 | S14: =IF($J14=1,D14,"") -> 24162 | T14: =IF($J214=0, D214,"") -> 25603 | U14: =IF($J14=1,F14,"") -> 5668 | V14: =IF($J214=0,F214,"") -> 2757 | W14: =IF($J14=1,G14,"") -> 37 | X14: =IF($J214=0,G214,"") -> 26 | Y14: =IF($J14=1,H14,"") -> 13.7 | Z14: =IF($J214=0,H214,"") -> 10.2
A15: ="HH"&TEXT(ROW()-5,"000") -> HH010 | B15: Oloitoktok A | C15: 7 | D15: 38929 | E15: River | F15: 4352 | G15: 44 | H15: 0.8 | I15: 0.42013242 | J15: 1 | S15: =IF($J15=1,D15,"") -> 38929 | T15: =IF($J215=0, D215,"") -> 18545 | U15: =IF($J15=1,F15,"") -> 4352 | V15: =IF($J215=0,F215,"") -> 5378 | W15: =IF($J15=1,G15,"") -> 44 | X15: =IF($J215=0,G215,"") -> 82 | Y15: =IF($J15=1,H15,"") -> 0.8 | Z15: =IF($J215=0,H215,"") -> 12.4
A16: ="HH"&TEXT(ROW()-5,"000") -> HH011 | B16: Kiserian | C16: 6 | D16: 37284 | E16: Vendor | F16: 5229 | G16: 54 | H16: 2.1 | I16: 0.83446741 | J16: 1 | S16: =IF($J16=1,D16,"") -> 37284 | T16: =IF($J216=0, D216,"") -> 26672 | U16: =IF($J16=1,F16,"") -> 5229 | V16: =IF($J216=0,F216,"") -> 3678 | W16: =IF($J16=1,G16,"") -> 54 | X16: =IF($J216=0,G216,"") -> 101 | Y16: =IF($J16=1,H16,"") -> 2.1 | Z16: =IF($J216=0,H216,"") -> 5.4
A17: ="HH"&TEXT(ROW()-5,"000") -> HH012 | B17: Kiserian | C17: 2 | D17: 35310 | E17: River | F17: 2816 | G17: 82 | H17: 15 | I17: 0.95057999 | J17: 1 | S17: =IF($J17=1,D17,"") -> 35310 | T17: =IF($J217=0, D217,"") -> 23679 | U17: =IF($J17=1,F17,"") -> 2816 | V17: =IF($J217=0,F217,"") -> 5387 | W17: =IF($J17=1,G17,"") -> 82 | X17: =IF($J217=0,G217,"") -> 102 | Y17: =IF($J17=1,H17,"") -> 15 | Z17: =IF($J217=0,H217,"") -> 7.2
A18: ="HH"&TEXT(ROW()-5,"000") -> HH013 | B18: Namanga | C18: 4 | D18: 30840 | E18: Vendor | F18: 5551 | G18: 63 | H18: 7.2 | I18: 0.03195723 | J18: 1 | S18: =IF($J18=1,D18,"") -> 30840 | T18: =IF($J218=0, D218,"") -> 32533 | U18: =IF($J18=1,F18,"") -> 5551 | V18: =IF($J218=0,F218,"") -> 2374 | W18: =IF($J18=1,G18,"") -> 63 | X18: =IF($J218=0,G218,"") -> 119 | Y18: =IF($J18=1,H18,"") -> 7.2 | Z18: =IF($J218=0,H218,"") -> 12.9
A19: ="HH"&TEXT(ROW()-5,"000") -> HH014 | B19: Kiserian | C19: 8 | D19: 30840 | E19: Borehole | F19: 7163 | G19: 94 | H19: 11.4 | I19: 0.77628902 | J19: 1 | S19: =IF($J19=1,D19,"") -> 30840 | T19: =IF($J219=0, D219,"") -> 27282 | U19: =IF($J19=1,F19,"") -> 7163 | V19: =IF($J219=0,F219,"") -> 4906 | W19: =IF($J19=1,G19,"") -> 94 | X19: =IF($J219=0,G219,"") -> 77 | Y19: =IF($J19=1,H19,"") -> 11.4 | Z19: =IF($J219=0,H219,"") -> 0.8
A20: ="HH"&TEXT(ROW()-5,"000") -> HH015 | B20: Kiserian | C20: 7 | D20: 17832 | E20: Borehole | F20: 5599 | G20: 81 | H20: 12 | I20: 0.73545476 | J20: 1 | S20: =IF($J20=1,D20,"") -> 17832 | T20: =IF($J220=0, D220,"") -> 18190 | U20: =IF($J20=1,F20,"") -> 5599 | V20: =IF($J220=0,F220,"") -> 3976 | W20: =IF($J20=1,G20,"") -> 81 | X20: =IF($J220=0,G220,"") -> 89 | Y20: =IF($J20=1,H20,"") -> 12 | Z20: =IF($J220=0,H220,"") -> 13.8
A21: ="HH"&TEXT(ROW()-5,"000") -> HH016 | B21: Oloitoktok A | C21: 8 | D21: 30692 | E21: River | F21: 7097 | G21: 45 | H21: 13.9 | I21: 0.54762515 | J21: 1 | S21: =IF($J21=1,D21,"") -> 30692 | T21: =IF($J221=0, D221,"") -> 28755 | U21: =IF($J21=1,F21,"") -> 7097 | V21: =IF($J221=0,F221,"") -> 4897 | W21: =IF($J21=1,G21,"") -> 45 | X21: =IF($J221=0,G221,"") -> 93 | Y21: =IF($J21=1,H21,"") -> 13.9 | Z21: =IF($J221=0,H221,"") -> 7.8
... A205: ="HH"&TEXT(ROW()-5,"000") -> HH200 | B205: Oloitoktok A | C205: 3 | D205: 18935 | E205: River | F205: 4709 | G205: 29 | H205: 13.2 | I205: 0.41796033 | J205: 1 | S205: =IF($J205=1,D205,"") -> 18935 | T205: =IF($J405=0, D405,"") -> 37920 | U205: =IF($J205=1,F205,"") -> 4709 | V205: =IF($J405=0,F405,"") -> 5831 | W205: =IF($J205=1,G205,"") -> 29 | X205: =IF($J405=0,G405,"") -> 120 | Y205: =IF($J205=1,H205,"") -> 13.2 | Z205: =IF($J405=0,H405,"") -> 8.4
A206: ="HH"&TEXT(ROW()-5,"000") -> HH201 | B206: Oloitoktok A | C206: 5 | D206: 23861 | E206: Rainwater | F206: 5945 | G206: 91 | H206: 3.5 | I206: 0.41929337 | J206: 0 | S206: =IF($J206=1,D206,"") | U206: =IF($J206=1,F206,"")
A207: ="HH"&TEXT(ROW()-5,"000") -> HH202 | B207: Namanga | C207: 6 | D207: 30323 | E207: River | F207: 5395 | G207: 29 | H207: 6.7 | I207: 0.67257935 | J207: 0 | S207: =IF($J207=1,D207,"") | U207: =IF($J207=1,F207,"")
A208: ="HH"&TEXT(ROW()-5,"000") -> HH203 | B208: Oloitoktok B | C208: 8 | D208: 27664 | E208: River | F208: 6942 | G208: 60 | H208: 11.2 | I208: 0.97116528 | J208: 0 | S208: =IF($J208=1,D208,"") | U208: =IF($J208=1,F208,"")
A209: ="HH"&TEXT(ROW()-5,"000") -> HH204 | B209: Kiserian | C209: 2 | D209: 22468 | E209: Vendor | F209: 2752 | G209: 50 | H209: 13.9 | I209: 0.81672678 | J209: 0 | S209: =IF($J209=1,D209,"") | U209: =IF($J209=1,F209,"")
A210: ="HH"&TEXT(ROW()-5,"000") -> HH205 | B210: Kiserian | C210: 8 | D210: 36674 | E210: Vendor | F210: 4730 | G210: 113 | H210: 7.2 | I210: 0.34107322 | J210: 0
A211: ="HH"&TEXT(ROW()-5,"000") -> HH206 | B211: Kiserian | C211: 2 | D211: 21108 | E211: Vendor | F211: 3739 | G211: 58 | H211: 10.4 | I211: 0.65705648 | J211: 0
A212: ="HH"&TEXT(ROW()-5,"000") -> HH207 | B212: Kiserian | C212: 7 | D212: 27803 | E212: Borehole | F212: 5478 | G212: 120 | H212: 14.2 | I212: 0.28595907 | J212: 0
A213: ="HH"&TEXT(ROW()-5,"000") -> HH208 | B213: Oloitoktok A | C213: 8 | D213: 37239 | E213: Borehole | F213: 7041 | G213: 114 | H213: 4.8 | I213: 0.42915868 | J213: 0
A214: ="HH"&TEXT(ROW()-5,"000") -> HH209 | B214: Oloitoktok A | C214: 3 | D214: 25603 | E214: Borehole | F214: 2757 | G214: 26 | H214: 10.2 | I214: 0.51944249 | J214: 0
A215: ="HH"&TEXT(ROW()-5,"000") -> HH210 | B215: Oloitoktok B | C215: 8 | D215: 18545 | E215: Borehole | F215: 5378 | G215: 82 | H215: 12.4 | I215: 0.014887332 | J215: 0
A216: ="HH"&TEXT(ROW()-5,"000") -> HH211 | B216: Oloitoktok A | C216: 3 | D216: 26672 | E216: Borehole | F216: 3678 | G216: 101 | H216: 5.4 | I216: 0.77322693 | J216: 0
A217: ="HH"&TEXT(ROW()-5,"000") -> HH212 | B217: Namanga | C217: 7 | D217: 23679 | E217: Borehole | F217: 5387 | G217: 102 | H217: 7.2 | I217: 0.75487434 | J217: 0
A218: ="HH"&TEXT(ROW()-5,"000") -> HH213 | B218: Oloitoktok B | C218: 2 | D218: 32533 | E218: Rainwater | F218: 2374 | G218: 119 | H218: 12.9 | I218: 0.63036936 | J218: 0
A219: ="HH"&TEXT(ROW()-5,"000") -> HH214 | B219: Namanga | C219: 8 | D219: 27282 | E219: River | F219: 4906 | G219: 77 | H219: 0.8 | I219: 0.070628848 | J219: 0
A220: ="HH"&TEXT(ROW()-5,"000") -> HH215 | B220: Namanga | C220: 2 | D220: 18190 | E220: River | F220: 3976 | G220: 89 | H220: 13.8 | I220: 0.057351159 | J220: 0
A221: ="HH"&TEXT(ROW()-5,"000") -> HH216 | B221: Oloitoktok A | C221: 8 | D221: 28755 | E221: River | F221: 4897 | G221: 93 | H221: 7.8 | I221: 0.88962472 | J221: 0
... A232: ="HH"&TEXT(ROW()-5,"000") -> HH227 | B232: Oloitoktok B | C232: 2 | D232: 26752 | E232: Vendor | F232: 3866 | G232: 105 | H232: 10.7 | I232: 0.48494026 | J232: 0
A233: ="HH"&TEXT(ROW()-5,"000") -> HH228 | B233: Kiserian | C233: 5 | D233: 24669 | E233: Vendor | F233: 5293 | G233: 77 | H233: 14.4 | I233: 0.42463667 | J233: 0 | S233: =IF($J233=1,D233,"")
A234: ="HH"&TEXT(ROW()-5,"000") -> HH229 | B234: Oloitoktok A | C234: 6 | D234: 29246 | E234: Vendor | F234: 5422 | G234: 88 | H234: 9.8 | I234: 0.93837508 | J234: 0 | S234: =IF($J234=1,D234,"")
...

Sheet Baseline_Characteristics_t-test
A1: t-Test: Two-Sample of Monthly incomes Treatment and Control groups | D1: t-Test: Two-Sample Assuming Equal Variances | G1: t-Test: Two-Sample Assuming Equal Variances | J1: t-Test: Two-Sample Assuming Equal Variances
A2: Monthly Income | D2: Health Expenditure | G2: Time used to collect water | J2: Distance to Health facility
B3: Treatment Income | C3: Control Group Income | E3: Treatment ANE | F3: Control ANE | H3: Treatment- Time | I3: Control- Time | K3: Treatment KM | L3: Control KM
A4: Mean | B4: 27664.405 | C4: 27790.695 | D4: Mean | E4: 4651.985 | F4: 4730.95 | G4: Mean | H4: 66.28 | I4: 65.29 | J4: Mean | K4: 7.5445 | L4: 7.683
A5: Variance | B5: 59572947 | C5: 49125894 | D5: Variance | E5: 1154562.8 | F5: 1063653.6 | G5: Variance | H5: 936.13226 | I5: 986.44814 | J5: Variance | K5: 18.701075 | L5: 18.094383
A6: Observations | B6: 200 | C6: 200 | D6: Observations | E6: 200 | F6: 200 | G6: Observations | H6: 200 | I6: 200 | J6: Observations | K6: 200 | L6: 200
A7: Pooled Variance | B7: 54349421 | D7: Pooled Variance | E7: 1109108.2 | G7: Pooled Variance | H7: 961.2902 | J7: Pooled Variance | K7: 18.397729
A8: Hypothesized Mean Difference | B8: 0 | D8: Hypothesized Mean Difference | E8: 0 | G8: Hypothesized Mean Difference | H8: 0 | J8: Hypothesized Mean Difference | K8: 0
A9: df | B9: 398 | D9: df | E9: 398 | G9: df | H9: 398 | J9: df | K9: 398
A10: t Stat | B10: -0.17130558 | D10: t Stat | E10: -0.74980388 | G10: t Stat | H10: 0.31930663 | J10: t Stat | K10: -0.32289972
A11: P(T<=t) one-tail | B11: 0.43203528 | D11: P(T<=t) one-tail | E11: 0.22690791 | G11: P(T<=t) one-tail | H11: 0.37483077 | J11: P(T<=t) one-tail | K11: 0.37347038
A12: t Critical one-tail | B12: 1.6486912 | D12: t Critical one-tail | E12: 1.6486912 | G12: t Critical one-tail | H12: 1.6486912 | J12: t Critical one-tail | K12: 1.6486912
A13: P(T<=t) two-tail | B13: 0.86407055 | D13: P(T<=t) two-tail | E13: 0.45381581 | G13: P(T<=t) two-tail | H13: 0.74966153 | J13: P(T<=t) two-tail | K13: 0.74694076
A14: t Critical two-tail | B14: 1.9659423 | D14: t Critical two-tail | E14: 1.9659423 | G14: t Critical two-tail | H14: 1.9659423 | J14: t Critical two-tail | K14: 1.9659423

Sheet Baseline_RCT
A2: Household ID | B2: Village | C2: Household_Size | D2: Monthly_Household_Income | E2: Current Water Source | F2: Annual Health Expenditure | G2: Time to collect Water | H2: Distance to Health facility | I2: Random No. | J2: Treatment
A3: HH001 | B3: Oloitoktok A | C3: 2 | D3: 17533 | E3: Borehole | F3: 3387 | G3: 96 | H3: 14.1 | I3: 0.14715147 | J3: 1
A4: HH002 | B4: Oloitoktok A | C4: 3 | D4: 28095 | E4: Rainwater | F4: 3285 | G4: 66 | H4: 8.5 | I4: 0.21625297 | J4: 1
A5: HH003 | B5: Namanga | C5: 7 | D5: 35172 | E5: Rainwater | F5: 6752 | G5: 42 | H5: 1.9 | I5: 0.87272995 | J5: 1
A6: HH004 | B6: Oloitoktok B | C6: 8 | D6: 24958 | E6: Rainwater | F6: 4888 | G6: 64 | H6: 12.3 | I6: 0.43294112 | J6: 1
A7: HH005 | B7: Oloitoktok B | C7: 4 | D7: 35107 | E7: Borehole | F7: 5527 | G7: 20 | H7: 14.7 | I7: 0.66002778 | J7: 1
A8: HH006 | B8: Namanga | C8: 4 | D8: 33442 | E8: Vendor | F8: 4457 | G8: 92 | H8: 11.3 | I8: 0.79246542 | J8: 1
A9: HH007 | B9: Oloitoktok B | C9: 2 | D9: 34829 | E9: Vendor | F9: 4225 | G9: 60 | H9: 10.5 | I9: 0.27764315 | J9: 1
A10: HH008 | B10: Kiserian | C10: 3 | D10: 33149 | E10: Vendor | F10: 2764 | G10: 70 | H10: 11.7 | I10: 0.74421109 | J10: 1
A11: HH009 | B11: Kiserian | C11: 6 | D11: 24162 | E11: Rainwater | F11: 5668 | G11: 37 | H11: 13.7 | I11: 0.41983377 | J11: 1
A12: HH010 | B12: Oloitoktok A | C12: 7 | D12: 38929 | E12: River | F12: 4352 | G12: 44 | H12: 0.8 | I12: 0.42013242 | J12: 1
A13: HH011 | B13: Kiserian | C13: 6 | D13: 37284 | E13: Vendor | F13: 5229 | G13: 54 | H13: 2.1 | I13: 0.83446741 | J13: 1
A14: HH012 | B14: Kiserian | C14: 2 | D14: 35310 | E14: River | F14: 2816 | G14: 82 | H14: 15 | I14: 0.95057999 | J14: 1
... A402: HH400 | B402: Oloitoktok B | C402: 7 | D402: 37920 | E402: Vendor | F402: 5831 | G402: 120 | H402: 8.4 | I402: 0.44901651 | J402: 0

Sheet Endline_Data_charecteristics
A1: Endline t-Test Analysis
A3: t-Test: Two-Sample Assuming Equal Variances | D3: t-Test: Two-Sample Assuming Equal Variances | G3: t-Test: Two-Sample Assuming Equal Variances
A4: Monthly Household Income | D4: Annual Health Expenditure | G4: Time spent to collect water
B5: Treatment | C5: Control | E5: Treatment | F5: Control | H5: Treatment | I5: Treatment
A6: Mean | B6: 31262.7 | C6: 28922.775 | D6: Mean | E6: 3305.515 | F6: 4660.295 | G6: Mean | H6: 29.325 | I6: 64.36
A7: Variance | B7: 66395312 | C7: 56165470 | D7: Variance | E7: 509947.52 | F7: 1078058.8 | G7: Variance | H7: 177.52701 | I7: 920.18131
A8: Observations | B8: 200 | C8: 200 | D8: Observations | E8: 200 | F8: 200 | G8: Observations | H8: 200 | I8: 200
A9: Pooled Variance | B9: 61280391 | D9: Pooled Variance | E9: 794003.15 | G9: Pooled Variance | H9: 548.85416
A10: Hypothesized Mean Difference | B10: 0 | D10: Hypothesized Mean Difference | E10: 0 | G10: Hypothesized Mean Difference | H10: 0
A11: df | B11: 398 | D11: df | E11: 398 | G11: df | H11: 398
A12: t Stat | B12: 2.989105 | D12: t Stat | E12: -15.203993 | G12: t Stat | H12: -14.95456
A13: P(T<=t) one-tail | B13: 0.0014857682 | D13: P(T<=t) one-tail | E13: 8.6965706e-42 | G13: P(T<=t) one-tail | H13: 9.625365e-41
A14: t Critical one-tail | B14: 1.6486912 | D14: t Critical one-tail | E14: 1.6486912 | G14: t Critical one-tail | H14: 1.6486912
A15: P(T<=t) two-tail | B15: 0.0029715364 | D15: P(T<=t) two-tail | E15: 1.7393141e-41 | G15: P(T<=t) two-tail | H15: 1.925073e-40
A16: t Critical two-tail | B16: 1.9659423 | D16: t Critical two-tail | E16: 1.9659423 | G16: t Critical two-tail | H16: 1.9659423

Sheet KRWSIP_Program_Endline_Data
B2: Endline Data of Evaluation Sample
R3: Treatment Group | S3: Comparison Group | T3: Difference
B4: Household ID | C4: Village | D4: Household_Size | E4: Treatment | F4: Household_Size | G4: Monthly_Household_Income | H4: Time to collect Water | I4: Current Water Source | J4: Annual Health Expenditure | K4: Time to collect Water | L4: Distance to Health facility | M4: Treatment | O4: =D4 -> Household_Size | R4: =AVERAGE(D5:D204) -> 4.98 | S4: =AVERAGE(D205:D404) -> 5.215 | T4: =R4-S4 -> -0.235 | V4: Treatment Income | W4: Control Income | X4: Treatment ANE | Y4: Control-ANE | Z4: TRG- Time | AA4: GTG-Time | AB4: TRG- Distance | AC4: CTr-Distance
B5: ="HH"&TEXT(ROW()-4, "000") -> HH001 | C5: Oloitoktok A | D5: 2 | E5: 1 | F5: 2 | G5: 19516 | H5: 36 | I5: Borehole | J5: 2426 | K5: 36 | L5: ='KRWSIP_Program_Baseline Data'!H6 -> 14.1 | M5: 1 | O5: =G4 -> Monthly_Household_Income | R5: =AVERAGE(G5:G204) -> 31262.7 | S5: =AVERAGE(G205:G404) -> 28922.775 | T5: =R5-S5 -> 2339.925 | V5: =IF($M5=1,G5,"") -> 19516 | W5: =IF($M205=0, G205,"") -> 24830 | X5: =IF($M5=1,J5,"") -> 2426 | Y5: =IF($M205=0,J205,"") -> 5681 | Z5: =IF($M5=1,K5,"") -> 36 | AA5: =IF($M205=0,K205,"") -> 88 | AB5: =IF($M5=1,L5,"") -> 14.1 | AC5: =IF($M205=0,L205,"") -> 3.5
B6: ="HH"&TEXT(ROW()-4, "000") -> HH002 | C6: Oloitoktok A | D6: 3 | E6: 1 | F6: 3 | G6: 31054 | H6: 31 | I6: Rainwater | J6: 2445 | K6: 31 | L6: ='KRWSIP_Program_Baseline Data'!H7 -> 8.5 | M6: 1 | O6: =J4 -> Annual Health Expenditure | R6: =AVERAGE(J5:J203) -> 3305.7437 | S6: =AVERAGE(J205:J404) -> 4660.295 | T6: =R6-S6 -> -1354.5513 | V6: =IF($M6=1,G6,"") -> 31054 | W6: =IF($M206=0, G206,"") -> 31429 | X6: =IF($M6=1,J6,"") -> 2445 | Y6: =IF($M206=0,J206,"") -> 5077 | Z6: =IF($M6=1,K6,"") -> 31 | AA6: =IF($M206=0,K206,"") -> 29 | AB6: =IF($M6=1,L6,"") -> 8.5 | AC6: =IF($M206=0,L206,"") -> 6.7
B7: ="HH"&TEXT(ROW()-4, "000") -> HH003 | C7: Namanga | D7: 7 | E7: 1 | F7: 7 | G7: 39285 | H7: 20 | I7: Rainwater | J7: 4620 | K7: 20 | L7: ='KRWSIP_Program_Baseline Data'!H8 -> 1.9 | M7: 1 | O7: =K4 -> Time to collect Water | R7: =AVERAGE(K5:K204) -> 29.325 | S7: =AVERAGE(K205:K404) -> 64.36 | T7: =R7-S7 -> -35.035 | V7: =IF($M7=1,G7,"") -> 39285 | W7: =IF($M207=0, G207,"") -> 28947 | X7: =IF($M7=1,J7,"") -> 4620 | Y7: =IF($M207=0,J207,"") -> 6477 | Z7: =IF($M7=1,K7,"") -> 20 | AA7: =IF($M207=0,K207,"") -> 59 | AB7: =IF($M7=1,L7,"") -> 1.9 | AC7: =IF($M207=0,L207,"") -> 11.2
B8: ="HH"&TEXT(ROW()-4, "000") -> HH004 | C8: Oloitoktok B | D8: 8 | E8: 1 | F8: 8 | G8: 27775 | H8: 27 | I8: Rainwater | J8: 3312 | K8: 27 | L8: ='KRWSIP_Program_Baseline Data'!H9 -> 12.3 | M8: 1 | O8: =L4 -> Distance to Health facility | R8: =AVERAGE(L5:L204) -> 8.1255 | S8: =AVERAGE(L205:L404) -> 7.6565 | T8: =R8-S8 -> 0.469 | V8: =IF($M8=1,G8,"") -> 27775 | W8: =IF($M208=0, G208,"") -> 23189 | X8: =IF($M8=1,J8,"") -> 3312 | Y8: =IF($M208=0,J208,"") -> 2641 | Z8: =IF($M8=1,K8,"") -> 27 | AA8: =IF($M208=0,K208,"") -> 46 | AB8: =IF($M8=1,L8,"") -> 12.3 | AC8: =IF($M208=0,L208,"") -> 13.9
B9: ="HH"&TEXT(ROW()-4, "000") -> HH005 | C9: Oloitoktok B | D9: 4 | E9: 1 | F9: 4 | G9: 38113 | H9: 9 | I9: Borehole | J9: 4120 | K9: 9 | L9: ='KRWSIP_Program_Baseline Data'!H10 -> 14.7 | M9: 1 | V9: =IF($M9=1,G9,"") -> 38113 | W9: =IF($M209=0, G209,"") -> 37703 | X9: =IF($M9=1,J9,"") -> 4120 | Y9: =IF($M209=0,J209,"") -> 4626 | Z9: =IF($M9=1,K9,"") -> 9 | AA9: =IF($M209=0,K209,"") -> 103 | AB9: =IF($M9=1,L9,"") -> 14.7 | AC9: =IF($M209=0,L209,"") -> 7.2
B10: ="HH"&TEXT(ROW()-4, "000") -> HH006 | C10: Namanga | D10: 4 | E10: 1 | F10: 4 | G10: 36615 | H10: 40 | I10: Vendor | J10: 2913 | K10: 40 | L10: ='KRWSIP_Program_Baseline Data'!H11 -> 11.3 | M10: 1 | V10: =IF($M10=1,G10,"") -> 36615 | W10: =IF($M210=0, G210,"") -> 21543 | X10: =IF($M10=1,J10,"") -> 2913 | Y10: =IF($M210=0,J210,"") -> 3620 | Z10: =IF($M10=1,K10,"") -> 40 | AA10: =IF($M210=0,K210,"") -> 53 | AB10: =IF($M10=1,L10,"") -> 11.3 | AC10: =IF($M210=0,L210,"") -> 10.4
B11: ="HH"&TEXT(ROW()-4, "000") -> HH007 | C11: Oloitoktok B | D11: 2 | E11: 1 | F11: 2 | G11: 38931 | H11: 27 | I11: Vendor | J11: 2814 | K11: 27 | L11: ='KRWSIP_Program_Baseline Data'!H12 -> 10.5 | M11: 1 | V11: =IF($M11=1,G11,"") -> 38931 | W11: =IF($M211=0, G211,"") -> 29013 | X11: =IF($M11=1,J11,"") -> 2814 | Y11: =IF($M211=0,J211,"") -> 5213 | Z11: =IF($M11=1,K11,"") -> 27 | AA11: =IF($M211=0,K211,"") -> 114 | AB11: =IF($M11=1,L11,"") -> 10.5 | AC11: =IF($M211=0,L211,"") -> 14.2
B12: ="HH"&TEXT(ROW()-4, "000") -> HH008 | C12: Kiserian | D12: 3 | E12: 1 | F12: 3 | G12: 36812 | H12: 32 | I12: Vendor | J12: 1836 | K12: 32 | L12: ='KRWSIP_Program_Baseline Data'!H13 -> 11.7 | M12: 1 | V12: =IF($M12=1,G12,"") -> 36812 | W12: =IF($M212=0, G212,"") -> 38238 | X12: =IF($M12=1,J12,"") -> 1836 | Y12: =IF($M212=0,J212,"") -> 6971 | Z12: =IF($M12=1,K12,"") -> 32 | AA12: =IF($M212=0,K212,"") -> 103 | AB12: =IF($M12=1,L12,"") -> 11.7 | AC12: =IF($M212=0,L212,"") -> 4.8
B13: ="HH"&TEXT(ROW()-4, "000") -> HH009 | C13: Kiserian | D13: 6 | E13: 1 | F13: 6 | G13: 26299 | H13: 17 | I13: Rainwater | J13: 3870 | K13: 17 | L13: ='KRWSIP_Program_Baseline Data'!H14 -> 13.7 | M13: 1 | V13: =IF($M13=1,G13,"") -> 26299 | W13: =IF($M213=0, G213,"") -> 26437 | X13: =IF($M13=1,J13,"") -> 3870 | Y13: =IF($M213=0,J213,"") -> 2677 | Z13: =IF($M13=1,K13,"") -> 17 | AA13: =IF($M213=0,K213,"") -> 24 | AB13: =IF($M13=1,L13,"") -> 13.7 | AC13: =IF($M213=0,L213,"") -> 10.2
B14: ="HH"&TEXT(ROW()-4, "000") -> HH010 | C14: Oloitoktok A | D14: 7 | E14: 1 | F14: 7 | G14: 42237 | H14: 16 | I14: River | J14: 2944 | K14: 16 | L14: ='KRWSIP_Program_Baseline Data'!H15 -> 0.8 | M14: 1 | V14: =IF($M14=1,G14,"") -> 42237 | W14: =IF($M214=0, G214,"") -> 19219 | X14: =IF($M14=1,J14,"") -> 2944 | Y14: =IF($M214=0,J214,"") -> 5116 | Z14: =IF($M14=1,K14,"") -> 16 | AA14: =IF($M214=0,K214,"") -> 80 | AB14: =IF($M14=1,L14,"") -> 0.8 | AC14: =IF($M214=0,L214,"") -> 12.4
B15: ="HH"&TEXT(ROW()-4, "000") -> HH011 | C15: Kiserian | D15: 6 | E15: 1 | F15: 6 | G15: 41606 | H15: 26 | I15: Vendor | J15: 3585 | K15: 26 | L15: ='KRWSIP_Program_Baseline Data'!H16 -> 2.1 | M15: 1 | V15: =IF($M15=1,G15,"") -> 41606 | W15: =IF($M215=0, G215,"") -> 27241 | X15: =IF($M15=1,J15,"") -> 3585 | Y15: =IF($M215=0,J215,"") -> 3432 | Z15: =IF($M15=1,K15,"") -> 26 | AA15: =IF($M215=0,K215,"") -> 96 | AB15: =IF($M15=1,L15,"") -> 2.1 | AC15: =IF($M215=0,L215,"") -> 5.4
B16: ="HH"&TEXT(ROW()-4, "000") -> HH012 | C16: Kiserian | D16: 2 | E16: 1 | F16: 2 | G16: 39207 | H16: 35 | I16: River | J16: 2096 | K16: 35 | L16: ='KRWSIP_Program_Baseline Data'!H17 -> 15 | M16: 1 | V16: =IF($M16=1,G16,"") -> 39207 | W16: =IF($M216=0, G216,"") -> 24530 | X16: =IF($M16=1,J16,"") -> 2096 | Y16: =IF($M216=0,J216,"") -> 5334 | Z16: =IF($M16=1,K16,"") -> 35 | AA16: =IF($M216=0,K216,"") -> 93 | AB16: =IF($M16=1,L16,"") -> 15 | AC16: =IF($M216=0,L216,"") -> 7.2
B17: ="HH"&TEXT(ROW()-4, "000") -> HH013 | C17: Namanga | D17: 4 | E17: 1 | F17: 4 | G17: 34419 | H17: 24 | I17: Vendor | J17: 4084 | K17: 24 | L17: ='KRWSIP_Program_Baseline Data'!H18 -> 7.2 | M17: 1 | V17: =IF($M17=1,G17,"") -> 34419 | W17: =IF($M217=0, G217,"") -> 33734 | X17: =IF($M17=1,J17,"") -> 4084 | Y17: =IF($M217=0,J217,"") -> 2263 | Z17: =IF($M17=1,K17,"") -> 24 | AA17: =IF($M217=0,K217,"") -> 119 | AB17: =IF($M17=1,L17,"") -> 7.2 | AC17: =IF($M217=0,L217,"") -> 12.9
B18: ="HH"&TEXT(ROW()-4, "000") -> HH014 | C18: Kiserian | D18: 8 | E18: 1 | F18: 8 | G18: 34518 | H18: 36 | I18: Borehole | J18: 4850 | K18: 36 | L18: ='KRWSIP_Program_Baseline Data'!H19 -> 11.4 | M18: 1 | V18: =IF($M18=1,G18,"") -> 34518 | W18: =IF($M218=0, G218,"") -> 27872 | X18: =IF($M18=1,J18,"") -> 4850 | Y18: =IF($M218=0,J218,"") -> 4830 | Z18: =IF($M18=1,K18,"") -> 36 | AA18: =IF($M218=0,K218,"") -> 77 | AB18: =IF($M18=1,L18,"") -> 11.4 | AC18: =IF($M218=0,L218,"") -> 0.8
B19: ="HH"&TEXT(ROW()-4, "000") -> HH015 | C19: Kiserian | D19: 7 | E19: 1 | F19: 7 | G19: 19886 | H19: 38 | I19: Borehole | J19: 3819 | K19: 38 | L19: ='KRWSIP_Program_Baseline Data'!H20 -> 12 | M19: 1 | V19: =IF($M19=1,G19,"") -> 19886 | W19: =IF($M219=0, G219,"") -> 18671 | X19: =IF($M19=1,J19,"") -> 3819 | Y19: =IF($M219=0,J219,"") -> 3961 | Z19: =IF($M19=1,K19,"") -> 38 | AA19: =IF($M219=0,K219,"") -> 88 | AB19: =IF($M19=1,L19,"") -> 12 | AC19: =IF($M219=0,L219,"") -> 13.8
B20: ="HH"&TEXT(ROW()-4, "000") -> HH016 | C20: Oloitoktok A | D20: 8 | E20: 1 | F20: 8 | G20: 33981 | H20: 21 | I20: River | J20: 4808 | K20: 21 | L20: ='KRWSIP_Program_Baseline Data'!H21 -> 13.9 | M20: 1 | V20: =IF($M20=1,G20,"") -> 33981 | W20: =IF($M220=0, G220,"") -> 29940 | X20: =IF($M20=1,J20,"") -> 4808 | Y20: =IF($M220=0,J220,"") -> 4738 | Z20: =IF($M20=1,K20,"") -> 21 | AA20: =IF($M220=0,K220,"") -> 90 | AB20: =IF($M20=1,L20,"") -> 13.9 | AC20: =IF($M220=0,L220,"") -> 7.8
... B204: ="HH"&TEXT(ROW()-4, "000") -> HH200 | C204: Oloitoktok A | D204: 3 | E204: 1 | F204: 3 | G204: 21060 | H204: 13 | I204: River | J204: 3260 | K204: 13 | L204: ='KRWSIP_Program_Baseline Data'!H205 -> 13.2 | M204: 1 | V204: =IF($M204=1,G204,"") -> 21060 | W204: =IF($M404=0, G404,"") -> 39267 | X204: =IF($M204=1,J204,"") -> 3260 | Y204: =IF($M404=0,J404,"") -> 5753 | Z204: =IF($M204=1,K204,"") -> 13 | AA204: =IF($M404=0,K404,"") -> 117 | AB204: =IF($M204=1,L204,"") -> 13.2 | AC204: =IF($M404=0,L404,"") -> 8.4
B205: ="HH"&TEXT(ROW()-4, "000") -> HH201 | C205: Oloitoktok A | D205: 5 | E205: 0 | F205: 5 | G205: 24830 | H205: 88 | I205: Rainwater | J205: 5681 | K205: 88 | L205: ='KRWSIP_Program_Baseline Data'!H206 -> 3.5 | M205: 0 | V205: =AVERAGE(V5:V204) -> 31262.7 | W205: =AVERAGE(W5:W204) -> 28922.775 | X205: =AVERAGE(X5:X204) -> 3305.515 | Y205: =AVERAGE(Y5:Y204) -> 4660.295 | Z205: =AVERAGE(Z5:Z204) -> 29.325 | AA205: =AVERAGE(AA5:AA204) -> 64.36 | AB205: =AVERAGE(AB5:AB204) -> 8.1255 | AC205: =AVERAGE(AC5:AC204) -> 7.6565
B206: ="HH"&TEXT(ROW()-4, "000") -> HH202 | C206: Namanga | D206: 6 | E206: 0 | F206: 6 | G206: 31429 | H206: 29 | I206: River | J206: 5077 | K206: 29 | L206: ='KRWSIP_Program_Baseline Data'!H207 -> 6.7 | M206: 0 | W206: =V205-W205 -> 2339.925 | X206: =IF($M206=1,J206,"") | Y206: =Y205-X205 -> 1354.78 | AA206: =Z205-AA205 -> -35.035 | AC206: =AB205-AC205 -> 0.469
B207: ="HH"&TEXT(ROW()-4, "000") -> HH203 | C207: Oloitoktok B | D207: 8 | E207: 0 | F207: 8 | G207: 28947 | H207: 59 | I207: River | J207: 6477 | K207: 59 | L207: ='KRWSIP_Program_Baseline Data'!H208 -> 11.2 | M207: 0 | V207: =IF($M207=1,G207,"") | X207: =IF($M207=1,J207,"")
B208: ="HH"&TEXT(ROW()-4, "000") -> HH204 | C208: Kiserian | D208: 2 | E208: 0 | F208: 2 | G208: 23189 | H208: 46 | I208: Vendor | J208: 2641 | K208: 46 | L208: ='KRWSIP_Program_Baseline Data'!H209 -> 13.9 | M208: 0 | V208: =IF($M208=1,G208,"") | X208: =IF($M208=1,J208,"")
B209: ="HH"&TEXT(ROW()-4, "000") -> HH205 | C209: Kiserian | D209: 8 | E209: 0 | F209: 8 | G209: 37703 | H209: 103 | I209: Vendor | J209: 4626 | K209: 103 | L209: ='KRWSIP_Program_Baseline Data'!H210 -> 7.2 | M209: 0
B210: ="HH"&TEXT(ROW()-4, "000") -> HH206 | C210: Kiserian | D210: 2 | E210: 0 | F210: 2 | G210: 21543 | H210: 53 | I210: Vendor | J210: 3620 | K210: 53 | L210: ='KRWSIP_Program_Baseline Data'!H211 -> 10.4 | M210: 0
B211: ="HH"&TEXT(ROW()-4, "000") -> HH207 | C211: Kiserian | D211: 7 | E211: 0 | F211: 7 | G211: 29013 | H211: 114 | I211: Borehole | J211: 5213 | K211: 114 | L211: ='KRWSIP_Program_Baseline Data'!H212 -> 14.2 | M211: 0
B212: ="HH"&TEXT(ROW()-4, "000") -> HH208 | C212: Oloitoktok A | D212: 8 | E212: 0 | F212: 8 | G212: 38238 | H212: 103 | I212: Borehole | J212: 6971 | K212: 103 | L212: ='KRWSIP_Program_Baseline Data'!H213 -> 4.8 | M212: 0
B213: ="HH"&TEXT(ROW()-4, "000") -> HH209 | C213: Oloitoktok A | D213: 3 | E213: 0 | F213: 3 | G213: 26437 | H213: 24 | I213: Borehole | J213: 2677 | K213: 24 | L213: ='KRWSIP_Program_Baseline Data'!H214 -> 10.2 | M213: 0
B214: ="HH"&TEXT(ROW()-4, "000") -> HH210 | C214: Oloitoktok B | D214: 8 | E214: 0 | F214: 8 | G214: 19219 | H214: 80 | I214: Borehole | J214: 5116 | K214: 80 | L214: ='KRWSIP_Program_Baseline Data'!H215 -> 12.4 | M214: 0
B215: ="HH"&TEXT(ROW()-4, "000") -> HH211 | C215: Oloitoktok A | D215: 3 | E215: 0 | F215: 3 | G215: 27241 | H215: 96 | I215: Borehole | J215: 3432 | K215: 96 | L215: ='KRWSIP_Program_Baseline Data'!H216 -> 5.4 | M215: 0
B216: ="HH"&TEXT(ROW()-4, "000") -> HH212 | C216: Namanga | D216: 7 | E216: 0 | F216: 7 | G216: 24530 | H216: 93 | I216: Borehole | J216: 5334 | K216: 93 | L216: ='KRWSIP_Program_Baseline Data'!H217 -> 7.2 | M216: 0
B217: ="HH"&TEXT(ROW()-4, "000") -> HH213 | C217: Oloitoktok B | D217: 2 | E217: 0 | F217: 2 | G217: 33734 | H217: 119 | I217: Rainwater | J217: 2263 | K217: 119 | L217: ='KRWSIP_Program_Baseline Data'!H218 -> 12.9 | M217: 0
B218: ="HH"&TEXT(ROW()-4, "000") -> HH214 | C218: Namanga | D218: 8 | E218: 0 | F218: 8 | G218: 27872 | H218: 77 | I218: River | J218: 4830 | K218: 77 | L218: ='KRWSIP_Program_Baseline Data'!H219 -> 0.8 | M218: 0
B219: ="HH"&TEXT(ROW()-4, "000") -> HH215 | C219: Namanga | D219: 2 | E219: 0 | F219: 2 | G219: 18671 | H219: 88 | I219: River | J219: 3961 | K219: 88 | L219: ='KRWSIP_Program_Baseline Data'!H220 -> 13.8 | M219: 0
B220: ="HH"&TEXT(ROW()-4, "000") -> HH216 | C220: Oloitoktok A | D220: 8 | E220: 0 | F220: 8 | G220: 29940 | H220: 90 | I220: River | J220: 4738 | K220: 90 | L220: ='KRWSIP_Program_Baseline Data'!H221 -> 7.8 | M220: 0
... B231: ="HH"&TEXT(ROW()-4, "000") -> HH227 | C231: Oloitoktok B | D231: 2 | E231: 0 | F231: 2 | G231: 27934 | H231: 101 | I231: Vendor | J231: 3830 | K231: 101 | L231: ='KRWSIP_Program_Baseline Data'!H232 -> 10.7 | M231: 0
B232: ="HH"&TEXT(ROW()-4, "000") -> HH228 | C232: Kiserian | D232: 5 | E232: 0 | F232: 5 | G232: 25667 | H232: 71 | I232: Vendor | J232: 5030 | K232: 71 | L232: ='KRWSIP_Program_Baseline Data'!H233 -> 14.4 | M232: 0 | V232: =IF($M232=1,G232,"")
B233: ="HH"&TEXT(ROW()-4, "000") -> HH229 | C233: Oloitoktok A | D233: 6 | E233: 0 | F233: 6 | G233: 30572 | H233: 84 | I233: Vendor | J233: 5067 | K233: 84 | L233: ='KRWSIP_Program_Baseline Data'!H234 -> 9.8 | M233: 0 | V233: =IF($M233=1,G233,"")
B234: ="HH"&TEXT(ROW()-4, "000") -> HH230 | C234: Namanga | D234: 3 | E234: 0 | F234: 3 | G234: 44501 | H234: 73 | I234: River | J234: 4224 | K234: 73 | L234: ='KRWSIP_Program_Baseline Data'!H235 -> 9.3 | M234: 0 | V234: =IF($M234=1,G234,"")
...

Sheet Endline_RCT
A2: Household ID | B2: Village | C2: Household_Size | D2: Treatment | E2: Household_Size | F2: Monthly_Household_Income | G2: Time to collect Water | H2: Current Water Source | I2: Annual Health Expenditure | J2: Distance to Health facility
A3: HH001 | B3: Oloitoktok A | C3: 2 | D3: 1 | E3: 2 | F3: 19516 | G3: 36 | H3: Borehole | I3: 2426 | J3: 14.1
A4: HH002 | B4: Oloitoktok A | C4: 3 | D4: 1 | E4: 3 | F4: 31054 | G4: 31 | H4: Rainwater | I4: 2445 | J4: 8.5
A5: HH003 | B5: Namanga | C5: 7 | D5: 1 | E5: 7 | F5: 39285 | G5: 20 | H5: Rainwater | I5: 4620 | J5: 1.9
A6: HH004 | B6: Oloitoktok B | C6: 8 | D6: 1 | E6: 8 | F6: 27775 | G6: 27 | H6: Rainwater | I6: 3312 | J6: 12.3
A7: HH005 | B7: Oloitoktok B | C7: 4 | D7: 1 | E7: 4 | F7: 38113 | G7: 9 | H7: Borehole | I7: 4120 | J7: 14.7
A8: HH006 | B8: Namanga | C8: 4 | D8: 1 | E8: 4 | F8: 36615 | G8: 40 | H8: Vendor | I8: 2913 | J8: 11.3
A9: HH007 | B9: Oloitoktok B | C9: 2 | D9: 1 | E9: 2 | F9: 38931 | G9: 27 | H9: Vendor | I9: 2814 | J9: 10.5
A10: HH008 | B10: Kiserian | C10: 3 | D10: 1 | E10: 3 | F10: 36812 | G10: 32 | H10: Vendor | I10: 1836 | J10: 11.7
A11: HH009 | B11: Kiserian | C11: 6 | D11: 1 | E11: 6 | F11: 26299 | G11: 17 | H11: Rainwater | I11: 3870 | J11: 13.7
A12: HH010 | B12: Oloitoktok A | C12: 7 | D12: 1 | E12: 7 | F12: 42237 | G12: 16 | H12: River | I12: 2944 | J12: 0.8
A13: HH011 | B13: Kiserian | C13: 6 | D13: 1 | E13: 6 | F13: 41606 | G13: 26 | H13: Vendor | I13: 3585 | J13: 2.1
A14: HH012 | B14: Kiserian | C14: 2 | D14: 1 | E14: 2 | F14: 39207 | G14: 35 | H14: River | I14: 2096 | J14: 15
... A402: HH400 | B402: Oloitoktok B | C402: 7 | D402: 0 | E402: 7 | F402: 39267 | G402: 117 | H402: Vendor | I402: 5753 | J402: 8.4

Sheet Graphs 
C1: Household Monthly Income | G1: Annual Health Expenditure | K1: Time spent to collect water
C2: Baseline | D2: Endline | G2: Baseline | H2: Endline | K2: Baseline | L2: Endline
B3: Treatment | C3: ='KRWSIP_Program_Baseline Data'!O6 -> 28408.135 | D3: =KRWSIP_Program_Endline_Data!R5 -> 31262.7 | F3: Treatment | G3: ='KRWSIP_Program_Baseline Data'!O7 -> 4730.1608 | H3: =KRWSIP_Program_Endline_Data!R6 -> 3305.7437 | J3: Treatment | K3: ='KRWSIP_Program_Baseline Data'!O8 -> 68.45 | L3: =KRWSIP_Program_Endline_Data!R7 -> 29.325
B4: Control | C4: ='KRWSIP_Program_Baseline Data'!P6 -> 27962.045 | D4: =KRWSIP_Program_Endline_Data!S5 -> 28922.775 | F4: Control | G4: ='KRWSIP_Program_Baseline Data'!P7 -> 4827.065 | H4: =KRWSIP_Program_Endline_Data!S6 -> 4660.295 | J4: Control | K4: ='KRWSIP_Program_Baseline Data'!P8 -> 67.855 | L4: =KRWSIP_Program_Endline_Data!S7 -> 64.36
B8: Time | C8: Treatment income | D8: Control Income | E8: Treatment Health Expenditure | F8: Control Health expenditure | G8: Treatment Time to collect water | H8: Control- Time to collect water
B9: Baseline | C9: =C3 -> 28408.135 | D9: =C4 -> 27962.045 | E9: =G3 -> 4730.1608 | F9: =H3 -> 3305.7437 | G9: ='KRWSIP_Program_Baseline Data'!O8 -> 68.45 | H9: ='KRWSIP_Program_Baseline Data'!P8 -> 67.855
B10: Endline | C10: =D3 -> 31262.7 | D10: =D4 -> 28922.775 | E10: =H3 -> 3305.7437 | F10: =H4 -> 4660.295 | G10: =KRWSIP_Program_Endline_Data!R7 -> 29.325 | H10: =KRWSIP_Program_Endline_Data!S7 -> 64.36

Sheet OLS_Regression Analysis
A1: Linear regression | K1: Multivariat Regression Analysis
A2: SUMMARY OUTPUT | K2: SUMMARY OUTPUT
A3: Regression Statistics | K3: Regression Statistics
A4: Multiple R | B4: 0.60614514 | K4: Multiple R | L4: 0.82402453
A5: R Square | B5: 0.36741193 | K5: R Square | L5: 0.67901643
A6: Adjusted R Square | B6: 0.36582251 | K6: Adjusted R Square | L6: 0.67576596
A7: Standard Error | B7: 891.06855 | K7: Standard Error | L7: 637.1402
A8: Observations | B8: 400 | K8: Observations | L8: 400
A10: ANOVA | K10: ANOVA
B11: df | C11: SS | D11: MS | E11: F | F11: Significance F | L11: df | M11: SS | N11: MS | O11: F | P11: Significance F
A12: Regression | B12: 1 | C12: 1.8354288e+08 | D12: 1.8354288e+08 | E12: 231.16141 | F12: 1.7393141e-41 | K12: Regression | L12: 4 | M12: 3.3920683e+08 | N12: 84801707 | O12: 208.89815 | P12: 4.5817072e-96
A13: Residual | B13: 398 | C13: 3.1601326e+08 | D13: 794003.15 | K13: Residual | L13: 395 | M13: 1.6034931e+08 | N13: 405947.63
A14: Total | B14: 399 | C14: 4.9955614e+08 | K14: Total | L14: 399 | M14: 4.9955614e+08
B16: Coefficients | C16: Standard Error | D16: t Stat | E16: P-value | F16: Lower 95% | G16: Upper 95% | H16: Lower 95.0% | I16: Upper 95.0% | L16: Coefficients | M16: Standard Error | N16: t Stat | O16: P-value | P16: Lower 95% | Q16: Upper 95% | R16: Lower 95.0% | S16: Upper 95.0%
A17: Intercept | B17: 4660.295 | C17: 63.008061 | D17: 73.963472 | E17: 1.1358744e-234 | F17: 4536.4248 | G17: 4784.1652 | H17: 4536.4248 | I17: 4784.1652 | K17: Intercept | L17: 3029.1997 | M17: 175.88648 | N17: 17.22247 | O17: 5.5036755e-50 | P17: 2683.409 | Q17: 3374.9904 | R17: 2683.409 | S17: 3374.9904
A18: Treatment | B18: -1354.78 | C18: 89.106855 | D18: -15.203993 | E18: 1.7393141e-41 | F18: -1529.9589 | G18: -1179.6011 | H18: -1529.9589 | I18: -1179.6011 | K18: Treatment | L18: -1328.8114 | M18: 79.848727 | N18: -16.641611 | O18: 1.6750768e-47 | P18: -1485.7931 | Q18: -1171.8298 | R18: -1485.7931 | S18: -1171.8298
K19: Household_Size | L19: 300.55778 | M19: 15.391191 | N19: 19.527909 | O19: 6.3002487e-60 | P19: 270.29888 | Q19: 330.81667 | R19: 270.29888 | S19: 330.81667
K20: Household_income | L20: 0.0043867203 | M20: 0.0040938344 | N20: 1.0715432 | O20: 0.28457953 | P20: -0.0036617084 | Q20: 0.012435149 | R20: -0.0036617084 | S20: 0.012435149
K21: Time_spent to collect water | L21: -0.98181592 | M21: 1.3690886 | N21: -0.71713104 | O21: 0.47371708 | P21: -3.6734275 | Q21: 1.7097956 | R21: -3.6734275 | S21: 1.7097956

Sheet Baseline2P
A1: Household ID | B1: Village | C1: Household_Size | D1: Monthly_Household_Income | E1: Current Water Source | F1: Time Spent Collecting water(Mins) | G1: Distance to Health facility(kms) | H1: Monthly Health Expenditure | I1: Random No. | J1: Treatment
A2: ="HH"&TEXT(ROW()-1,"000") -> HH001 | B2: =LOOKUP(RAND(),{0,0.28,0.55,0.78},{"Oloitoktok A","Oloitoktok B","Kiserian","Namanga"}) -> Oloitoktok A | C2: =LOOKUP(RAND(),{0,0.02,0.09,0.2,0.35,0.52,0.68,0.81,0.91,0.97},{1,2,3,4,5,6,7,8,9,10}) -> 5 | D2: =MAX(5000,MIN(150000,ROUND(_xlfn.LOGNORM.INV(RAND(),LN(28000+1500*C2),0.55),-2))) -> 65100 | E2: =IF(B2="Oloitoktok A",IF(D2<15000,LOOKUP(RAND(),{0,0.45,0.75,0.92},{"River","Rainwater","Borehole","Vendor"}),IF(D2<30000,LOOKUP(RAND(),{0,0.35,0.65,0.85},{"River","Rainwater","Borehole","Vendor"}),LOOKUP(RAND(),{0,0.25,0.5,0.75},{"River","Rainwater","Borehole","Vendor"}))),IF(B2="Oloitoktok B",IF(D2<15000,LOOKUP(RAND(),{0,0.5,0.78,0.94},{"River","Rainwater","Borehole","Vendor"}),IF(D2<30000,LOOKUP(RAND(),{0,0.4,0.68,0.87},{"River","Rainwater","Borehole","Vendor"}),LOOKUP(RAND(),{0,0.28,0.55,0.78},{"River","Rainwater","Borehole","Vendor"}))),IF(B2="Kiserian",IF(D2<15000,LOOKUP(RAND(),{0,0.35,0.65,0.9},{"River","Rainwater","Borehole","Vendor"}),IF(D2<30000,LOOKUP(RAND(),{0,0.25,0.55,0.82},{"River","Rainwater","Borehole","Vendor"}),LOOKUP(RAND(),{0,0.15,0.45,0.72},{"River","Rainwater","Borehole","Vendor"}))),IF(D2<15000,LOOKUP(RAND(),{0,0.4,0.7,0.92},{"River","Rainwater","Borehole","Vendor"}),IF(D2<30000,LOOKUP(RAND(),{0,0.3,0.6,0.85},{"River","Rainwater","Borehole","Vendor"}),LOOKUP(RAND(),{0,0.2,0.5,0.75},{"River","Rainwater","Borehole","Vendor"})))))) -> Rainwater | F2: =IF(E2="River",RANDBETWEEN(45,120),IF(E2="Rainwater",RANDBETWEEN(15,70),IF(E2="Borehole",RANDBETWEEN(20,75),RANDBETWEEN(10,60)))) -> 66 | G2: =IF(B2="Oloitoktok A",ROUND(RANDBETWEEN(5,150)/10,1),IF(B2="Oloitoktok B",ROUND(RANDBETWEEN(4,140)/10,1),IF(B2="Kiserian",ROUND(RANDBETWEEN(2,100)/10,1),ROUND(RANDBETWEEN(3,120)/10,1)))) -> 11.8 | H2: =MAX(0,ROUND((1500+(C2*250)+(D2*0.025)+(F2*8)+(G2*120)+IF(E2="River",1200,IF(E2="Rainwater",700,IF(E2="Borehole",400,200)))+_xlfn.NORM.INV(RAND(),0,3500)),-2)) -> 1600 | I2: =RAND() -> 0.21590193 | J2: 0
A3: ="HH"&TEXT(ROW()-1,"000") -> HH002 | B3: =LOOKUP(RAND(),{0,0.28,0.55,0.78},{"Oloitoktok A","Oloitoktok B","Kiserian","Namanga"}) -> Oloitoktok B | C3: =LOOKUP(RAND(),{0,0.02,0.09,0.2,0.35,0.52,0.68,0.81,0.91,0.97},{1,2,3,4,5,6,7,8,9,10}) -> 6 | D3: =MAX(5000,MIN(150000,ROUND(_xlfn.LOGNORM.INV(RAND(),LN(28000+1500*C3),0.55),-2))) -> 18900 | E3: =IF(B3="Oloitoktok A",IF(D3<15000,LOOKUP(RAND(),{0,0.45,0.75,0.92},{"River","Rainwater","Borehole","Vendor"}),IF(D3<30000,LOOKUP(RAND(),{0,0.35,0.65,0.85},{"River","Rainwater","Borehole","Vendor"}),LOOKUP(RAND(),{0,0.25,0.5,0.75},{"River","Rainwater","Borehole","Vendor"}))),IF(B3="Oloitoktok B",IF(D3<15000,LOOKUP(RAND(),{0,0.5,0.78,0.94},{"River","Rainwater","Borehole","Vendor"}),IF(D3<30000,LOOKUP(RAND(),{0,0.4,0.68,0.87},{"River","Rainwater","Borehole","Vendor"}),LOOKUP(RAND(),{0,0.28,0.55,0.78},{"River","Rainwater","Borehole","Vendor"}))),IF(B3="Kiserian",IF(D3<15000,LOOKUP(RAND(),{0,0.35,0.65,0.9},{"River","Rainwater","Borehole","Vendor"}),IF(D3<30000,LOOKUP(RAND(),{0,0.25,0.55,0.82},{"River","Rainwater","Borehole","Vendor"}),LOOKUP(RAND(),{0,0.15,0.45,0.72},{"River","Rainwater","Borehole","Vendor"}))),IF(D3<15000,LOOKUP(RAND(),{0,0.4,0.7,0.92},{"River","Rainwater","Borehole","Vendor"}),IF(D3<30000,LOOKUP(RAND(),{0,0.3,0.6,0.85},{"River","Rainwater","Borehole","Vendor"}),LOOKUP(RAND(),{0,0.2,0.5,0.75},{"River","Rainwater","Borehole","Vendor"})))))) -> Rainwater | F3: =IF(E3="River",RANDBETWEEN(45,120),IF(E3="Rainwater",RANDBETWEEN(15,70),IF(E3="Borehole",RANDBETWEEN(20,75),RANDBETWEEN(10,60)))) -> 35 | G3: =IF(B3="Oloitoktok A",ROUND(RANDBETWEEN(5,150)/10,1),IF(B3="Oloitoktok B",ROUND(RANDBETWEEN(4,140)/10,1),IF(B3="Kiserian",ROUND(RANDBETWEEN(2,100)/10,1),ROUND(RANDBETWEEN(3,120)/10,1)))) -> 9.9 | H3: =MAX(0,ROUND((1500+(C3*250)+(D3*0.025)+(F3*8)+(G3*120)+IF(E3="River",1200,IF(E3="Rainwater",700,IF(E3="Borehole",400,200)))+_xlfn.NORM.INV(RAND(),0,3500)),-2)) -> 0 | I3: =RAND() -> 0.38200945 | J3: 0
A4: ="HH"&TEXT(ROW()-1,"000") -> HH003 | B4: =LOOKUP(RAND(),{0,0.28,0.55,0.78},{"Oloitoktok A","Oloitoktok B","Kiserian","Namanga"}) -> Oloitoktok A | C4: =LOOKUP(RAND(),{0,0.02,0.09,0.2,0.35,0.52,0.68,0.81,0.91,0.97},{1,2,3,4,5,6,7,8,9,10}) -> 5 | D4: =MAX(5000,MIN(150000,ROUND(_xlfn.LOGNORM.INV(RAND(),LN(28000+1500*C4),0.55),-2))) -> 71800 | E4: =IF(B4="Oloitoktok A",IF(D4<15000,LOOKUP(RAND(),{0,0.45,0.75,0.92},{"River","Rainwater","Borehole","Vendor"}),IF(D4<30000,LOOKUP(RAND(),{0,0.35,0.65,0.85},{"River","Rainwater","Borehole","Vendor"}),LOOKUP(RAND(),{0,0.25,0.5,0.75},{"River","Rainwater","Borehole","Vendor"}))),IF(B4="Oloitoktok B",IF(D4<15000,LOOKUP(RAND(),{0,0.5,0.78,0.94},{"River","Rainwater","Borehole","Vendor"}),IF(D4<30000,LOOKUP(RAND(),{0,0.4,0.68,0.87},{"River","Rainwater","Borehole","Vendor"}),LOOKUP(RAND(),{0,0.28,0.55,0.78},{"River","Rainwater","Borehole","Vendor"}))),IF(B4="Kiserian",IF(D4<15000,LOOKUP(RAND(),{0,0.35,0.65,0.9},{"River","Rainwater","Borehole","Vendor"}),IF(D4<30000,LOOKUP(RAND(),{0,0.25,0.55,0.82},{"River","Rainwater","Borehole","Vendor"}),LOOKUP(RAND(),{0,0.15,0.45,0.72},{"River","Rainwater","Borehole","Vendor"}))),IF(D4<15000,LOOKUP(RAND(),{0,0.4,0.7,0.92},{"River","Rainwater","Borehole","Vendor"}),IF(D4<30000,LOOKUP(RAND(),{0,0.3,0.6,0.85},{"River","Rainwater","Borehole","Vendor"}),LOOKUP(RAND(),{0,0.2,0.5,0.75},{"River","Rainwater","Borehole","Vendor"})))))) -> Borehole | F4: =IF(E4="River",RANDBETWEEN(45,120),IF(E4="Rainwater",RANDBETWEEN(15,70),IF(E4="Borehole",RANDBETWEEN(20,75),RANDBETWEEN(10,60)))) -> 28 | G4: =IF(B4="Oloitoktok A",ROUND(RANDBETWEEN(5,150)/10,1),IF(B4="Oloitoktok B",ROUND(RANDBETWEEN(4,140)/10,1),IF(B4="Kiserian",ROUND(RANDBETWEEN(2,100)/10,1),ROUND(RANDBETWEEN(3,120)/10,1)))) -> 7.7 | H4: =MAX(0,ROUND((1500+(C4*250)+(D4*0.025)+(F4*8)+(G4*120)+IF(E4="River",1200,IF(E4="Rainwater",700,IF(E4="Borehole",400,200)))+_xlfn.NORM.INV(RAND(),0,3500)),-2)) -> 4900 | I4: =RAND() -> 0.85054225 | J4: 0
A5: ="HH"&TEXT(ROW()-1,"000") -> HH004 | B5: =LOOKUP(RAND(),{0,0.28,0.55,0.78},{"Oloitoktok A","Oloitoktok B","Kiserian","Namanga"}) -> Kiserian | C5: =LOOKUP(RAND(),{0,0.02,0.09,0.2,0.35,0.52,0.68,0.81,0.91,0.97},{1,2,3,4,5,6,7,8,9,10}) -> 3 | D5: =MAX(5000,MIN(150000,ROUND(_xlfn.LOGNORM.INV(RAND(),LN(28000+1500*C5),0.55),-2))) -> 26300 | E5: =IF(B5="Oloitoktok A",IF(D5<15000,LOOKUP(RAND(),{0,0.45,0.75,0.92},{"River","Rainwater","Borehole","Vendor"}),IF(D5<30000,LOOKUP(RAND(),{0,0.35,0.65,0.85},{"River","Rainwater","Borehole","Vendor"}),LOOKUP(RAND(),{0,0.25,0.5,0.75},{"River","Rainwater","Borehole","Vendor"}))),IF(B5="Oloitoktok B",IF(D5<15000,LOOKUP(RAND(),{0,0.5,0.78,0.94},{"River","Rainwater","Borehole","Vendor"}),IF(D5<30000,LOOKUP(RAND(),{0,0.4,0.68,0.87},{"River","Rainwater","Borehole","Vendor"}),LOOKUP(RAND(),{0,0.28,0.55,0.78},{"River","Rainwater","Borehole","Vendor"}))),IF(B5="Kiserian",IF(D5<15000,LOOKUP(RAND(),{0,0.35,0.65,0.9},{"River","Rainwater","Borehole","Vendor"}),IF(D5<30000,LOOKUP(RAND(),{0,0.25,0.55,0.82},{"River","Rainwater","Borehole","Vendor"}),LOOKUP(RAND(),{0,0.15,0.45,0.72},{"River","Rainwater","Borehole","Vendor"}))),IF(D5<15000,LOOKUP(RAND(),{0,0.4,0.7,0.92},{"River","Rainwater","Borehole","Vendor"}),IF(D5<30000,LOOKUP(RAND(),{0,0.3,0.6,0.85},{"River","Rainwater","Borehole","Vendor"}),LOOKUP(RAND(),{0,0.2,0.5,0.75},{"River","Rainwater","Borehole","Vendor"})))))) -> Rainwater | F5: =IF(E5="River",RANDBETWEEN(45,120),IF(E5="Rainwater",RANDBETWEEN(15,70),IF(E5="Borehole",RANDBETWEEN(20,75),RANDBETWEEN(10,60)))) -> 38 | G5: =IF(B5="Oloitoktok A",ROUND(RANDBETWEEN(5,150)/10,1),IF(B5="Oloitoktok B",ROUND(RANDBETWEEN(4,140)/10,1),IF(B5="Kiserian",ROUND(RANDBETWEEN(2,100)/10,1),ROUND(RANDBETWEEN(3,120)/10,1)))) -> 4.8 | H5: =MAX(0,ROUND((1500+(C5*250)+(D5*0.025)+(F5*8)+(G5*120)+IF(E5="River",1200,IF(E5="Rainwater",700,IF(E5="Borehole",400,200)))+_xlfn.NORM.INV(RAND(),0,3500)),-2)) -> 6700 | I5: =RAND() -> 0.23105006 | J5: 0
A6: ="HH"&TEXT(ROW()-1,"000") -> HH005 | B6: =LOOKUP(RAND(),{0,0.28,0.55,0.78},{"Oloitoktok A","Oloitoktok B","Kiserian","Namanga"}) -> Oloitoktok B | C6: =LOOKUP(RAND(),{0,0.02,0.09,0.2,0.35,0.52,0.68,0.81,0.91,0.97},{1,2,3,4,5,6,7,8,9,10}) -> 8 | D6: =MAX(5000,MIN(150000,ROUND(_xlfn.LOGNORM.INV(RAND(),LN(28000+1500*C6),0.55),-2))) -> 24200 | E6: =IF(B6="Oloitoktok A",IF(D6<15000,LOOKUP(RAND(),{0,0.45,0.75,0.92},{"River","Rainwater","Borehole","Vendor"}),IF(D6<30000,LOOKUP(RAND(),{0,0.35,0.65,0.85},{"River","Rainwater","Borehole","Vendor"}),LOOKUP(RAND(),{0,0.25,0.5,0.75},{"River","Rainwater","Borehole","Vendor"}))),IF(B6="Oloitoktok B",IF(D6<15000,LOOKUP(RAND(),{0,0.5,0.78,0.94},{"River","Rainwater","Borehole","Vendor"}),IF(D6<30000,LOOKUP(RAND(),{0,0.4,0.68,0.87},{"River","Rainwater","Borehole","Vendor"}),LOOKUP(RAND(),{0,0.28,0.55,0.78},{"River","Rainwater","Borehole","Vendor"}))),IF(B6="Kiserian",IF(D6<15000,LOOKUP(RAND(),{0,0.35,0.65,0.9},{"River","Rainwater","Borehole","Vendor"}),IF(D6<30000,LOOKUP(RAND(),{0,0.25,0.55,0.82},{"River","Rainwater","Borehole","Vendor"}),LOOKUP(RAND(),{0,0.15,0.45,0.72},{"River","Rainwater","Borehole","Vendor"}))),IF(D6<15000,LOOKUP(RAND(),{0,0.4,0.7,0.92},{"River","Rainwater","Borehole","Vendor"}),IF(D6<30000,LOOKUP(RAND(),{0,0.3,0.6,0.85},{"River","Rainwater","Borehole","Vendor"}),LOOKUP(RAND(),{0,0.2,0.5,0.75},{"River","Rainwater","Borehole","Vendor"})))))) -> Vendor | F6: =IF(E6="River",RANDBETWEEN(45,120),IF(E6="Rainwater",RANDBETWEEN(15,70),IF(E6="Borehole",RANDBETWEEN(20,75),RANDBETWEEN(10,60)))) -> 19 | G6: =IF(B6="Oloitoktok A",ROUND(RANDBETWEEN(5,150)/10,1),IF(B6="Oloitoktok B",ROUND(RANDBETWEEN(4,140)/10,1),IF(B6="Kiserian",ROUND(RANDBETWEEN(2,100)/10,1),ROUND(RANDBETWEEN(3,120)/10,1)))) -> 2.2 | H6: =MAX(0,ROUND((1500+(C6*250)+(D6*0.025)+(F6*8)+(G6*120)+IF(E6="River",1200,IF(E6="Rainwater",700,IF(E6="Borehole",400,200)))+_xlfn.NORM.INV(RAND(),0,3500)),-2)) -> 5600 | I6: =RAND() -> 0.32322297 | J6: 0
A7: ="HH"&TEXT(ROW()-1,"000") -> HH006 | B7: =LOOKUP(RAND(),{0,0.28,0.55,0.78},{"Oloitoktok A","Oloitoktok B","Kiserian","Namanga"}) -> Kiserian | C7: =LOOKUP(RAND(),{0,0.02,0.09,0.2,0.35,0.52,0.68,0.81,0.91,0.97},{1,2,3,4,5,6,7,8,9,10}) -> 6 | D7: =MAX(5000,MIN(150000,ROUND(_xlfn.LOGNORM.INV(RAND(),LN(28000+1500*C7),0.55),-2))) -> 20000 | E7: =IF(B7="Oloitoktok A",IF(D7<15000,LOOKUP(RAND(),{0,0.45,0.75,0.92},{"River","Rainwater","Borehole","Vendor"}),IF(D7<30000,LOOKUP(RAND(),{0,0.35,0.65,0.85},{"River","Rainwater","Borehole","Vendor"}),LOOKUP(RAND(),{0,0.25,0.5,0.75},{"River","Rainwater","Borehole","Vendor"}))),IF(B7="Oloitoktok B",IF(D7<15000,LOOKUP(RAND(),{0,0.5,0.78,0.94},{"River","Rainwater","Borehole","Vendor"}),IF(D7<30000,LOOKUP(RAND(),{0,0.4,0.68,0.87},{"River","Rainwater","Borehole","Vendor"}),LOOKUP(RAND(),{0,0.28,0.55,0.78},{"River","Rainwater","Borehole","Vendor"}))),IF(B7="Kiserian",IF(D7<15000,LOOKUP(RAND(),{0,0.35,0.65,0.9},{"River","Rainwater","Borehole","Vendor"}),IF(D7<30000,LOOKUP(RAND(),{0,0.25,0.55,0.82},{"River","Rainwater","Borehole","Vendor"}),LOOKUP(RAND(),{0,0.15,0.45,0.72},{"River","Rainwater","Borehole","Vendor"}))),IF(D7<15000,LOOKUP(RAND(),{0,0.4,0.7,0.92},{"River","Rainwater","Borehole","Vendor"}),IF(D7<30000,LOOKUP(RAND(),{0,0.3,0.6,0.85},{"River","Rainwater","Borehole","Vendor"}),LOOKUP(RAND(),{0,0.2,0.5,0.75},{"River","Rainwater","Borehole","Vendor"})))))) -> Borehole | F7: =IF(E7="River",RANDBETWEEN(45,120),IF(E7="Rainwater",RANDBETWEEN(15,70),IF(E7="Borehole",RANDBETWEEN(20,75),RANDBETWEEN(10,60)))) -> 64 | G7: =IF(B7="Oloitoktok A",ROUND(RANDBETWEEN(5,150)/10,1),IF(B7="Oloitoktok B",ROUND(RANDBETWEEN(4,140)/10,1),IF(B7="Kiserian",ROUND(RANDBETWEEN(2,100)/10,1),ROUND(RANDBETWEEN(3,120)/10,1)))) -> 4.5 | H7: =MAX(0,ROUND((1500+(C7*250)+(D7*0.025)+(F7*8)+(G7*120)+IF(E7="River",1200,IF(E7="Rainwater",700,IF(E7="Borehole",400,200)))+_xlfn.NORM.INV(RAND(),0,3500)),-2)) -> 5600 | I7: =RAND() -> 0.67701238 | J7: 0
A8: ="HH"&TEXT(ROW()-1,"000") -> HH007 | B8: =LOOKUP(RAND(),{0,0.28,0.55,0.78},{"Oloitoktok A","Oloitoktok B","Kiserian","Namanga"}) -> Oloitoktok A | C8: =LOOKUP(RAND(),{0,0.02,0.09,0.2,0.35,0.52,0.68,0.81,0.91,0.97},{1,2,3,4,5,6,7,8,9,10}) -> 6 | D8: =MAX(5000,MIN(150000,ROUND(_xlfn.LOGNORM.INV(RAND(),LN(28000+1500*C8),0.55),-2))) -> 27800 | E8: =IF(B8="Oloitoktok A",IF(D8<15000,LOOKUP(RAND(),{0,0.45,0.75,0.92},{"River","Rainwater","Borehole","Vendor"}),IF(D8<30000,LOOKUP(RAND(),{0,0.35,0.65,0.85},{"River","Rainwater","Borehole","Vendor"}),LOOKUP(RAND(),{0,0.25,0.5,0.75},{"River","Rainwater","Borehole","Vendor"}))),IF(B8="Oloitoktok B",IF(D8<15000,LOOKUP(RAND(),{0,0.5,0.78,0.94},{"River","Rainwater","Borehole","Vendor"}),IF(D8<30000,LOOKUP(RAND(),{0,0.4,0.68,0.87},{"River","Rainwater","Borehole","Vendor"}),LOOKUP(RAND(),{0,0.28,0.55,0.78},{"River","Rainwater","Borehole","Vendor"}))),IF(B8="Kiserian",IF(D8<15000,LOOKUP(RAND(),{0,0.35,0.65,0.9},{"River","Rainwater","Borehole","Vendor"}),IF(D8<30000,LOOKUP(RAND(),{0,0.25,0.55,0.82},{"River","Rainwater","Borehole","Vendor"}),LOOKUP(RAND(),{0,0.15,0.45,0.72},{"River","Rainwater","Borehole","Vendor"}))),IF(D8<15000,LOOKUP(RAND(),{0,0.4,0.7,0.92},{"River","Rainwater","Borehole","Vendor"}),IF(D8<30000,LOOKUP(RAND(),{0,0.3,0.6,0.85},{"River","Rainwater","Borehole","Vendor"}),LOOKUP(RAND(),{0,0.2,0.5,0.75},{"River","Rainwater","Borehole","Vendor"})))))) -> Rainwater | F8: =IF(E8="River",RANDBETWEEN(45,120),IF(E8="Rainwater",RANDBETWEEN(15,70),IF(E8="Borehole",RANDBETWEEN(20,75),RANDBETWEEN(10,60)))) -> 42 | G8: =IF(B8="Oloitoktok A",ROUND(RANDBETWEEN(5,150)/10,1),IF(B8="Oloitoktok B",ROUND(RANDBETWEEN(4,140)/10,1),IF(B8="Kiserian",ROUND(RANDBETWEEN(2,100)/10,1),ROUND(RANDBETWEEN(3,120)/10,1)))) -> 6.7 | H8: =MAX(0,ROUND((1500+(C8*250)+(D8*0.025)+(F8*8)+(G8*120)+IF(E8="River",1200,IF(E8="Rainwater",700,IF(E8="Borehole",400,200)))+_xlfn.NORM.INV(RAND(),0,3500)),-2)) -> 3200 | I8: =RAND() -> 0.13893133 | J8: 0
A9: ="HH"&TEXT(ROW()-1,"000") -> HH008 | B9: =LOOKUP(RAND(),{0,0.28,0.55,0.78},{"Oloitoktok A","Oloitoktok B","Kiserian","Namanga"}) -> Namanga | C9: =LOOKUP(RAND(),{0,0.02,0.09,0.2,0.35,0.52,0.68,0.81,0.91,0.97},{1,2,3,4,5,6,7,8,9,10}) -> 5 | D9: =MAX(5000,MIN(150000,ROUND(_xlfn.LOGNORM.INV(RAND(),LN(28000+1500*C9),0.55),-2))) -> 45400 | E9: =IF(B9="Oloitoktok A",IF(D9<15000,LOOKUP(RAND(),{0,0.45,0.75,0.92},{"River","Rainwater","Borehole","Vendor"}),IF(D9<30000,LOOKUP(RAND(),{0,0.35,0.65,0.85},{"River","Rainwater","Borehole","Vendor"}),LOOKUP(RAND(),{0,0.25,0.5,0.75},{"River","Rainwater","Borehole","Vendor"}))),IF(B9="Oloitoktok B",IF(D9<15000,LOOKUP(RAND(),{0,0.5,0.78,0.94},{"River","Rainwater","Borehole","Vendor"}),IF(D9<30000,LOOKUP(RAND(),{0,0.4,0.68,0.87},{"River","Rainwater","Borehole","Vendor"}),LOOKUP(RAND(),{0,0.28,0.55,0.78},{"River","Rainwater","Borehole","Vendor"}))),IF(B9="Kiserian",IF(D9<15000,LOOKUP(RAND(),{0,0.35,0.65,0.9},{"River","Rainwater","Borehole","Vendor"}),IF(D9<30000,LOOKUP(RAND(),{0,0.25,0.55,0.82},{"River","Rainwater","Borehole","Vendor"}),LOOKUP(RAND(),{0,0.15,0.45,0.72},{"River","Rainwater","Borehole","Vendor"}))),IF(D9<15000,LOOKUP(RAND(),{0,0.4,0.7,0.92},{"River","Rainwater","Borehole","Vendor"}),IF(D9<30000,LOOKUP(RAND(),{0,0.3,0.6,0.85},{"River","Rainwater","Borehole","Vendor"}),LOOKUP(RAND(),{0,0.2,0.5,0.75},{"River","Rainwater","Borehole","Vendor"})))))) -> Vendor | F9: =IF(E9="River",RANDBETWEEN(45,120),IF(E9="Rainwater",RANDBETWEEN(15,70),IF(E9="Borehole",RANDBETWEEN(20,75),RANDBETWEEN(10,60)))) -> 30 | G9: =IF(B9="Oloitoktok A",ROUND(RANDBETWEEN(5,150)/10,1),IF(B9="Oloitoktok B",ROUND(RANDBETWEEN(4,140)/10,1),IF(B9="Kiserian",ROUND(RANDBETWEEN(2,100)/10,1),ROUND(RANDBETWEEN(3,120)/10,1)))) -> 0.4 | H9: =MAX(0,ROUND((1500+(C9*250)+(D9*0.025)+(F9*8)+(G9*120)+IF(E9="River",1200,IF(E9="Rainwater",700,IF(E9="Borehole",400,200)))+_xlfn.NORM.INV(RAND(),0,3500)),-2)) -> 8200 | I9: =RAND() -> 0.55057134 | J9: 0
A10: ="HH"&TEXT(ROW()-1,"000") -> HH009 | B10: =LOOKUP(RAND(),{0,0.28,0.55,0.78},{"Oloitoktok A","Oloitoktok B","Kiserian","Namanga"}) -> Oloitoktok B | C10: =LOOKUP(RAND(),{0,0.02,0.09,0.2,0.35,0.52,0.68,0.81,0.91,0.97},{1,2,3,4,5,6,7,8,9,10}) -> 6 | D10: =MAX(5000,MIN(150000,ROUND(_xlfn.LOGNORM.INV(RAND(),LN(28000+1500*C10),0.55),-2))) -> 37500 | E10: =IF(B10="Oloitoktok A",IF(D10<15000,LOOKUP(RAND(),{0,0.45,0.75,0.92},{"River","Rainwater","Borehole","Vendor"}),IF(D10<30000,LOOKUP(RAND(),{0,0.35,0.65,0.85},{"River","Rainwater","Borehole","Vendor"}),LOOKUP(RAND(),{0,0.25,0.5,0.75},{"River","Rainwater","Borehole","Vendor"}))),IF(B10="Oloitoktok B",IF(D10<15000,LOOKUP(RAND(),{0,0.5,0.78,0.94},{"River","Rainwater","Borehole","Vendor"}),IF(D10<30000,LOOKUP(RAND(),{0,0.4,0.68,0.87},{"River","Rainwater","Borehole","Vendor"}),LOOKUP(RAND(),{0,0.28,0.55,0.78},{"River","Rainwater","Borehole","Vendor"}))),IF(B10="Kiserian",IF(D10<15000,LOOKUP(RAND(),{0,0.35,0.65,0.9},{"River","Rainwater","Borehole","Vendor"}),IF(D10<30000,LOOKUP(RAND(),{0,0.25,0.55,0.82},{"River","Rainwater","Borehole","Vendor"}),LOOKUP(RAND(),{0,0.15,0.45,0.72},{"River","Rainwater","Borehole","Vendor"}))),IF(D10<15000,LOOKUP(RAND(),{0,0.4,0.7,0.92},{"River","Rainwater","Borehole","Vendor"}),IF(D10<30000,LOOKUP(RAND(),{0,0.3,0.6,0.85},{"River","Rainwater","Borehole","Vendor"}),LOOKUP(RAND(),{0,0.2,0.5,0.75},{"River","Rainwater","Borehole","Vendor"})))))) -> Borehole | F10: =IF(E10="River",RANDBETWEEN(45,120),IF(E10="Rainwater",RANDBETWEEN(15,70),IF(E10="Borehole",RANDBETWEEN(20,75),RANDBETWEEN(10,60)))) -> 53 | G10: =IF(B10="Oloitoktok A",ROUND(RANDBETWEEN(5,150)/10,1),IF(B10="Oloitoktok B",ROUND(RANDBETWEEN(4,140)/10,1),IF(B10="Kiserian",ROUND(RANDBETWEEN(2,100)/10,1),ROUND(RANDBETWEEN(3,120)/10,1)))) -> 9.9 | H10: =MAX(0,ROUND((1500+(C10*250)+(D10*0.025)+(F10*8)+(G10*120)+IF(E10="River",1200,IF(E10="Rainwater",700,IF(E10="Borehole",400,200)))+_xlfn.NORM.INV(RAND(),0,3500)),-2)) -> 2600 | I10: =RAND() -> 0.84801958 | J10: 0
A11: ="HH"&TEXT(ROW()-1,"000") -> HH010 | B11: =LOOKUP(RAND(),{0,0.28,0.55,0.78},{"Oloitoktok A","Oloitoktok B","Kiserian","Namanga"}) -> Oloitoktok B | C11: =LOOKUP(RAND(),{0,0.02,0.09,0.2,0.35,0.52,0.68,0.81,0.91,0.97},{1,2,3,4,5,6,7,8,9,10}) -> 6 | D11: =MAX(5000,MIN(150000,ROUND(_xlfn.LOGNORM.INV(RAND(),LN(28000+1500*C11),0.55),-2))) -> 85300 | E11: =IF(B11="Oloitoktok A",IF(D11<15000,LOOKUP(RAND(),{0,0.45,0.75,0.92},{"River","Rainwater","Borehole","Vendor"}),IF(D11<30000,LOOKUP(RAND(),{0,0.35,0.65,0.85},{"River","Rainwater","Borehole","Vendor"}),LOOKUP(RAND(),{0,0.25,0.5,0.75},{"River","Rainwater","Borehole","Vendor"}))),IF(B11="Oloitoktok B",IF(D11<15000,LOOKUP(RAND(),{0,0.5,0.78,0.94},{"River","Rainwater","Borehole","Vendor"}),IF(D11<30000,LOOKUP(RAND(),{0,0.4,0.68,0.87},{"River","Rainwater","Borehole","Vendor"}),LOOKUP(RAND(),{0,0.28,0.55,0.78},{"River","Rainwater","Borehole","Vendor"}))),IF(B11="Kiserian",IF(D11<15000,LOOKUP(RAND(),{0,0.35,0.65,0.9},{"River","Rainwater","Borehole","Vendor"}),IF(D11<30000,LOOKUP(RAND(),{0,0.25,0.55,0.82},{"River","Rainwater","Borehole","Vendor"}),LOOKUP(RAND(),{0,0.15,0.45,0.72},{"River","Rainwater","Borehole","Vendor"}))),IF(D11<15000,LOOKUP(RAND(),{0,0.4,0.7,0.92},{"River","Rainwater","Borehole","Vendor"}),IF(D11<30000,LOOKUP(RAND(),{0,0.3,0.6,0.85},{"River","Rainwater","Borehole","Vendor"}),LOOKUP(RAND(),{0,0.2,0.5,0.75},{"River","Rainwater","Borehole","Vendor"})))))) -> Rainwater | F11: =IF(E11="River",RANDBETWEEN(45,120),IF(E11="Rainwater",RANDBETWEEN(15,70),IF(E11="Borehole",RANDBETWEEN(20,75),RANDBETWEEN(10,60)))) -> 64 | G11: =IF(B11="Oloitoktok A",ROUND(RANDBETWEEN(5,150)/10,1),IF(B11="Oloitoktok B",ROUND(RANDBETWEEN(4,140)/10,1),IF(B11="Kiserian",ROUND(RANDBETWEEN(2,100)/10,1),ROUND(RANDBETWEEN(3,120)/10,1)))) -> 10.5 | H11: =MAX(0,ROUND((1500+(C11*250)+(D11*0.025)+(F11*8)+(G11*120)+IF(E11="River",1200,IF(E11="Rainwater",700,IF(E11="Borehole",400,200)))+_xlfn.NORM.INV(RAND(),0,3500)),-2)) -> 11100 | I11: =RAND() -> 0.4498148 | J11: 0
